Workbook
Name Slicer_Category: #N/A

Sheet Sales_Transactions
A1: OrderID | B1: OrderDate | C1: ClientID | D1: ProductID | E1: SalesRepID | F1: Quantity | G1: UnitPrice | H1: Discount_pct | I1: Region | J1: DealStatus | K1: PaymentTerms | L1: Currency | M1: Revenue
A2: ORD-1110 | B2: 44956 | C2: CLI-043 | D2: PRD-07 | E2: REP-07 | F2: 10 | G2: 1750 | H2: N/A | I2: Asia-Pacific | J2: Won | K2: Immediate | L2: USD | M2: N/A
A3: ORD-1063 | B3: 45398 | C3: CLI-025 | D3: PRD-04 | E3: REP-04 | F3: 2 | G3: 400 | H3: 20 | I3: North America | J3: Won | K3: Net 30 | L3: EUR | M3: 640
A4: ORD-1121 | B4: 45141 | C4: CLI-056 | D4: PRD-02 | E4: REP-04 | F4: 0 | G4: 800 | H4: N/A | I4: N/A | J4: Pending | K4: Net 15 | L4: USD | M4: N/A
A5: ORD-1178 | B5: 45543 | C5: CLI-012 | D5: PRD-12 | E5: REP-01 | F5: 0 | G5: 1100 | H5: 0 | I5: N/A | J5: Pending | K5: Net30 | L5: EUR | M5: 0
A6: ORD-1235 | B6: 45062 | C6: CLI-042 | D6: PRD-03 | E6: REP-02 | F6: 2 | G6: 1500 | H6: 5 | I6: Asia-Pacific | J6: Pending | K6: Quarterly | L6: EUR | M6: 2850
A7: ORD-1016 | B7: 45417 | C7: CLI-026 | D7: PRD-12 | E7: REP-12 | F7: 5 | G7: 1100 | H7: 5 | I7: N/A | J7: Lost | K7: Net 60 | L7: INR | M7: 5225
A8: ORD-1148 | B8: 45303 | C8: CLI-032 | D8: PRD-10 | E8: REP-03 | F8: 3 | G8: 1900 | H8: 5 | I8: India | J8: Won | K8: Immediate | L8: EUR | M8: 5415 | N8: =_xlfn.XLOOKUP(Sales_Transactions!C2,Sales_Transactions!C2:C251,Sales_Transactions!C1:C251) -> #VALUE!
A9: ORD-1126 | B9: 45304 | C9: CLI-048 | D9: PRD-05 | E9: REP-12 | F9: 10 | G9: 2000 | H9: N/A | I9: India | J9: Won | K9: Net 60 | L9: EUR | M9: N/A
A10: ORD-1072 | B10: 45499 | C10: CLI-013 | D10: PRD-10 | E10: REP-12 | F10: 10 | G10: 1900 | H10: 15 | I10: Europe | J10: Lost | K10: Net 30 | L10: USD | M10: 16150
A11: ORD-1054 | B11: 45392 | C11: CLI-009 | D11: PRD-08 | E11: REP-03 | F11: 5 | G11: 2200 | H11: N/A | I11: India | J11: Won | K11: Immediate | L11: EUR | M11: N/A
A12: ORD-1103 | B12: 45483 | C12: CLI-033 | D12: PRD-12 | E12: REP-07 | F12: 4 | G12: 1100 | H12: 5 | I12: North America | J12: Won | K12: Net30 | L12: USD | M12: 4180
A13: ORD-1209 | B13: 45310 | C13: CLI-007 | D13: PRD-01 | E13: REP-09 | F13: 3 | G13: 1200 | H13: 5 | I13: Asia-Pacific | J13: Won | K13: Net30 | L13: INR | M13: 3420
A14: ORD-1061 | B14: 45479 | C14: CLI-006 | D14: PRD-11 | E14: REP-11 | F14: 4 | G14: 500 | H14: 5 | I14: N/A | J14: In Progress | K14: Annual | L14: EUR | M14: 1900
A15: ORD-1092 | B15: 45368 | C15: CLI-009 | D15: PRD-02 | E15: REP-03 | F15: -1 | G15: 800 | H15: N/A | I15: North America | J15: Won | K15: Net 60 | L15: INR | M15: N/A
A16: ORD-1245 | B16: 45225 | C16: CLI-022 | D16: PRD-06 | E16: REP-11 | F16: 1 | G16: 950 | H16: 0 | I16: N/A | J16: Pending | K16: Net 15 | L16: EUR | M16: 950
A17: ORD-1086 | B17: 45139 | C17: CLI-060 | D17: PRD-06 | E17: REP-01 | F17: 5 | G17: 950 | H17: 5 | I17: Europe | J17: Closed Won | K17: Immediate | L17: EUR | M17: 4512.5
A18: ORD-1021 | B18: 45198 | C18: CLI-003 | D18: PRD-11 | E18: REP-10 | F18: 0 | G18: 500 | H18: N/A | I18: India | J18: Won | K18: Quarterly | L18: EUR | M18: N/A
A19: ORD-1007 | B19: 45556 | C19: CLI-003 | D19: PRD-12 | E19: REP-06 | F19: 3 | G19: 1100 | H19: 0 | I19: North America | J19: Closed Lost | K19: Net30 | L19: EUR | M19: 3300
A20: ORD-1056 | B20: 45134 | C20: CLI-054 | D20: PRD-09 | E20: REP-09 | F20: 2 | G20: 700 | H20: N/A | I20: India | J20: Pending | K20: Net 60 | L20: EUR | M20: N/A
A21: ORD-1024 | B21: 45280 | C21: CLI-056 | D21: PRD-12 | E21: REP-06 | F21: 2 | G21: 1100 | H21: N/A | I21: India | J21: In Progress | K21: Net 60 | L21: INR | M21: N/A
A22: ORD-1017 | B22: 45279 | C22: CLI-030 | D22: PRD-11 | E22: REP-09 | F22: -1 | G22: 500 | H22: 10 | I22: N/A | J22: Closed Lost | K22: Net 30 | L22: USD | M22: -450
A23: ORD-1225 | B23: 45474 | C23: CLI-057 | D23: PRD-11 | E23: REP-05 | F23: 0 | G23: 500 | H23: 0 | I23: Middle East and Africa | J23: Won | K23: Net 30 | L23: USD | M23: 0
A24: ORD-1083 | B24: 45158 | C24: CLI-030 | D24: PRD-10 | E24: REP-04 | F24: 1 | G24: 1900 | H24: 0 | I24: North America | J24: Closed Lost | K24: Annual | L24: INR | M24: 1900
A25: ORD-1202 | B25: 44956 | C25: CLI-050 | D25: PRD-09 | E25: REP-10 | F25: 2 | G25: 700 | H25: 15 | I25: North America | J25: Won | K25: Net 30 | L25: INR | M25: 1190
A26: ORD-1025 | B26: 44936 | C26: CLI-016 | D26: PRD-08 | E26: REP-02 | F26: 2 | G26: 2200 | H26: 10 | I26: North America | J26: Won | K26: Net 30 | L26: INR | M26: 3960
A27: ORD-1217 | B27: 45451 | C27: CLI-013 | D27: PRD-06 | E27: REP-07 | F27: 2 | G27: 950 | H27: N/A | I27: Middle East and Africa | J27: Closed Won | K27: Net 60 | L27: INR | M27: N/A
A28: ORD-1120 | B28: 45180 | C28: CLI-014 | D28: PRD-07 | E28: REP-02 | F28: 1 | G28: 1750 | H28: N/A | I28: Europe | J28: Lost | K28: Net 60 | L28: INR | M28: N/A
A29: ORD-1223 | B29: 45277 | C29: CLI-057 | D29: PRD-11 | E29: REP-03 | F29: 4 | G29: 500 | H29: 15 | I29: N/A | J29: Closed Lost | K29: Net 30 | L29: USD | M29: 1700
A30: ORD-1022 | B30: 45088 | C30: CLI-035 | D30: PRD-05 | E30: REP-11 | F30: 2 | G30: 2000 | H30: N/A | I30: Europe | J30: Pending | K30: Net 60 | L30: EUR | M30: N/A
A31: ORD-1187 | B31: 45084 | C31: CLI-037 | D31: PRD-09 | E31: REP-08 | F31: 4 | G31: 700 | H31: 0 | I31: Asia-Pacific | J31: Won | K31: Net 30 | L31: EUR | M31: 2800
A32: ORD-1203 | B32: 45130 | C32: CLI-004 | D32: PRD-06 | E32: REP-12 | F32: 4 | G32: 950 | H32: N/A | I32: India | J32: Closed Lost | K32: Net 60 | L32: EUR | M32: N/A
A33: ORD-1244 | B33: 45452 | C33: CLI-022 | D33: PRD-09 | E33: REP-10 | F33: 4 | G33: 700 | H33: N/A | I33: North America | J33: Won | K33: Immediate | L33: USD | M33: N/A
A34: ORD-1039 | B34: 45277 | C34: CLI-012 | D34: PRD-08 | E34: REP-09 | F34: 3 | G34: 2200 | H34: N/A | I34: North America | J34: Won | K34: Net 30 | L34: EUR | M34: N/A
A35: ORD-1197 | B35: 45475 | C35: CLI-037 | D35: PRD-02 | E35: REP-05 | F35: 5 | G35: 800 | H35: 20 | I35: Asia-Pacific | J35: Pending | K35: Quarterly | L35: USD | M35: 3200
A36: ORD-1211 | B36: 45070 | C36: CLI-026 | D36: PRD-11 | E36: REP-06 | F36: 10 | G36: 500 | H36: 20 | I36: Europe | J36: Closed Lost | K36: Annual | L36: INR | M36: 4000
A37: ORD-1169 | B37: 45448 | C37: CLI-051 | D37: PRD-12 | E37: REP-06 | F37: 4 | G37: 1100 | H37: N/A | I37: Asia-Pacific | J37: Lost | K37: Net 15 | L37: USD | M37: N/A
A38: ORD-1081 | B38: 45208 | C38: CLI-002 | D38: PRD-09 | E38: REP-12 | F38: 1 | G38: 700 | H38: N/A | I38: N/A | J38: Won | K38: Net 60 | L38: EUR | M38: N/A
A39: ORD-1111 | B39: 45518 | C39: CLI-018 | D39: PRD-12 | E39: REP-02 | F39: -1 | G39: 1100 | H39: 10 | I39: Europe | J39: Lost | K39: Immediate | L39: INR | M39: -990
A40: ORD-1243 | B40: 45238 | C40: CLI-051 | D40: PRD-10 | E40: REP-10 | F40: 10 | G40: 1900 | H40: N/A | I40: Europe | J40: Won | K40: Immediate | L40: INR | M40: N/A
...

Sheet Clients
A1: ClientID | B1: CompanyName | C1: Industry | D1: Country | E1: CompanySize | F1: SignupDate | G1: AccountManager | H1: Email
A2: CLI-001 | B2: Wildcrest Energy | C2: Media & Entertainment | D2: France | E2: Medium (51-500) | F2: 13/12/2023 | G2: Vikram Nair | H2: contact@wildcrestenergy.com
A3: CLI-002 | B3: Brightmind Finance Group | C3: Manufacturing | D3: Brazil | E3: Large (500+) | F3: 12/06/2020 | G3: Ananya Sharma | H3: contact@brightmindfinancegroup.com
A4: CLI-003 | B4: Ashford Analytics | C4: Energy | D4: Germany | E4: Small and Medium-Sized Business | F4: 25/07/2023 | G4: Nikhil Pillai | H4: contact@ashfordanalytics.com
A5: CLI-004 | B5: Kestrel Labs | C5: Media & Entertainment | D5: United Kingdom | E5: Large (500+) | F5: 08/12/2023 | G5: Ananya Verma | H5: contact@kestrellabs.com
A6: CLI-005 | B6: Silverline Analytics | C6: Insurance | D6: Singapore | E6: Medium (51-500) | F6: 29/12/2022 | G6: Rahul Pillai | H6: contact@silverlineanalytics.com
A7: CLI-006 | B7: Solara Systems | C7: Education | D7: India | E7: Large (500+) | F7: 03/08/2023 | G7: Rahul Pillai | H7: contact@solarasystems.com
A8: CLI-007 | B8: Meridian Solutions | C8: Media & Entertainment | D8: Japan | E8: Small (1-50) | F8: 14/04/2021 | G8: Divya Reddy | H8: contact@meridiansolutions.com
A9: CLI-008 | B9: Thornton Labs | C9: Energy | D9: Germany | E9: Small (1-50) | F9: 08/03/2021 | G9: Arjun Rao | H9: contact@thorntonlabs.com
A10: CLI-009 | B10: Wildcrest Manufacturing | C10: Media & Entertainment | D10: United Kingdom | E10: Small and Medium-Sized Business | F10: 21/03/2022 | G10: Ananya Verma | H10: contact@wildcrestmanufacturing.com
A11: CLI-010 | B11: Halcyon Systems | C11: Logistics | D11: UK | E11: Medium (51-500) | F11: 23/02/2023 | G11: Arjun Reddy | H11: contact@halcyonsystems.com
A12: CLI-011 | B12: Pinnacle Manufacturing | C12: Insurance | D12: India | E12: Enterprise | F12: 28/03/2022 | G12: Nikhil Pillai | H12: contact@pinnaclemanufacturing.com
... A61: CLI-060 | B61: Ember Systems | C61: Manufacturing | D61: Japan | E61: Medium (51-500) | F61: 28/12/2020 | G61: Karthik Gupta | H61: contact@embersystems.com

Sheet Products
A1: ProductID | B1: ProductName | C1: Category | D1: LaunchDate | E1: PriceTier | F1: ListPrice_USD
A2: PRD-01 | B2: AI Sales Copilot | C2: Sales AI | D2: 44571 | E2: Premium | F2: 1200
A3: PRD-02 | B3: Predictive Lead Scoring | C3: Sales AI | D3: 44348 | E3: Standard | F3: 800
A4: PRD-03 | B4: Chatbot Suite Pro | C4: Conversational AI | D4: 44150 | E4: Premium | F4: 1500
A5: PRD-04 | B5: Chatbot Suite Lite | C5: Conversational AI | D5: 44150 | E5: Basic | F5: 400
A6: PRD-05 | B6: Document Intelligence | C6: Data AI | D6: 44977 | E6: Premium | F6: 2000
A7: PRD-06 | B7: Customer Churn Predictor | C7: Analytics AI | D7: 44778 | E7: Standard | F7: 950
A8: PRD-07 | B8: Demand Forecasting Engine | C8: Analytics AI | D8: 44267 | E8: Premium | F8: 1750
A9: PRD-08 | B9: Vision QC Inspector | C9: Computer Vision | D9: 45108 | E9: Premium | F9: 2200
A10: PRD-09 | B10: HR Resume Screener | C10: HR AI | D10: 44699 | E10: Standard | F10: 700
A11: PRD-10 | B11: Fraud Detection Shield | C11: Security AI | D11: 44448 | E11: Premium | F11: 1900
A12: PRD-11 | B12: Marketing Content Generator | C12: Generative AI | D12: 45027 | E12: Basic | F12: 500
A13: PRD-12 | B13: Voice Analytics Suite | C13: Conversational AI | D13: 44896 | E13: Standard | F13: 1100

Sheet Sales_Reps
A1: RepID | B1: RepName | C1: Region | D1: Team | E1: HireDate | F1: Email
A2: REP-01 | B2: Divya Reddy | C2: North America | D2: Small and Medium-Sized Business | E2: 44029 | F2: divya.reddy@neuracore.ai
A3: REP-02 | B3: Vikram Nair | C3: Europe | D3: Small and Medium-Sized Business | E3: 43675 | F3: vikram.nair@neuracore.ai
A4: REP-03 | B4: Divya Pillai | C4: North America | D4: Small and Medium-Sized Business | E4: 44330 | F4: divya.pillai@neuracore.ai
A5: REP-04 | B5: Ananya Sharma | C5: North America | D5: Enterprise | E5: 43942 | F5: ananya.sharma@neuracore.ai
A6: REP-05 | B6: Meera Choudhury | C6: North America | D6: Small and Medium-Sized Business | E6: 43873 | F6: meera.choudhury@neuracore.ai
A7: REP-06 | B7: Nikhil Pillai | C7: India | D7: Enterprise | E7: 44385 | F7: nikhil.pillai@neuracore.ai
A8: REP-07 | B8: Karthik Gupta | C8: North America | D8: Enterprise | E8: 44895 | F8: karthik.gupta@neuracore.ai
A9: REP-08 | B9: Kavya Rao | C9: Asia-Pacific | D9: Enterprise | E9: 43906 | F9: kavya.rao@neuracore.ai
A10: REP-09 | B10: Arjun Reddy | C10: North America | D10: Mid-Market | E10: 43664 | F10: arjun.reddy@neuracore.ai
A11: REP-10 | B11: Arjun Rao | C11: Middle East and Africa | D11: Mid-Market | E11: 45118 | F11: arjun.rao@neuracore.ai
A12: REP-11 | B12: Ananya Verma | C12: Middle East and Africa | D12: Enterprise | E12: 44241 | F12: ananya.verma@neuracore.ai
A13: REP-12 | B13: Rahul Pillai | C13: Asia-Pacific | D13: Small and Medium-Sized Business | E13: 44732 | F13: rahul.pillai@neuracore.ai

Sheet Support_Tickets
A1: TicketID | B1: ClientID | C1: DateRaised | D1: IssueType | E1: ResolutionTime_Hrs | F1: SatisfactionScore | G1: Status
A2: TKT-0001 | B2: CLI-028 | C2: 45065 | D2: Feature Request | E2: -3 | F2: 3 | G2: Escalated
A3: TKT-0002 | B3: CLI-054 | C3: 45358 | D3: Billing Query | E3: 54.1 | F3: N/A | G3: Pending
A4: TKT-0003 | B4: CLI-003 | C4: 44928 | D4: API Error | E4: 34.4 | F4: 4 | G4: Pending
A5: TKT-0004 | B5: CLI-017 | C5: 45304 | D5: Billing Query | E5: -3 | F5: 4 | G5: Pending
A6: TKT-0005 | B6: CLI-013 | C6: 45004 | D6: Billing Query | E6: 50.3 | F6: 3 | G6: Open
A7: TKT-0006 | B7: CLI-028 | C7: 45306 | D7: Onboarding Help | E7: N/A | F7: N/A | G7: Escalated
A8: TKT-0007 | B8: CLI-030 | C8: 45083 | D8: Feature Request | E8: 0 | F8: 4 | G8: Closed
A9: TKT-0008 | B9: CLI-053 | C9: 45201 | D9: API Error | E9: -3 | F9: 3 | G9: Open
A10: TKT-0009 | B10: CLI-032 | C10: 45259 | D10: Data Sync Error | E10: 50.6 | F10: 5 | G10: Open
A11: TKT-0010 | B11: CLI-034 | C11: 45122 | D11: API Error | E11: 0 | F11: 4 | G11: Escalated
A12: TKT-0011 | B12: CLI-002 | C12: 45022 | D12: API Error | E12: N/A | F12: 4 | G12: Pending
A13: TKT-0012 | B13: CLI-036 | C13: 45265 | D13: Data Sync Error | E13: 9.1 | F13: 2 | G13: Closed
A14: TKT-0013 | B14: CLI-048 | C14: 45422 | D14: Onboarding Help | E14: 26.3 | F14: 1 | G14: Pending
A15: TKT-0014 | B15: CLI-035 | C15: 45056 | D15: Login Issue | E15: 0 | F15: 1 | G15: Escalated
A16: TKT-0015 | B16: CLI-001 | C16: 45514 | D16: Data Sync Error | E16: 24.9 | F16: N/A | G16: Open
A17: TKT-0016 | B17: CLI-026 | C17: 45430 | D17: Login Issue | E17: -3 | F17: 5 | G17: Open
A18: TKT-0017 | B18: CLI-051 | C18: 45158 | D18: Data Sync Error | E18: 65.5 | F18: 5 | G18: Pending
A19: TKT-0018 | B19: CLI-007 | C19: 44934 | D19: Bug Report | E19: 0 | F19: N/A | G19: Open
A20: TKT-0019 | B20: CLI-031 | C20: 45225 | D20: API Error | E20: 17.2 | F20: N/A | G20: Escalated
A21: TKT-0020 | B21: CLI-041 | C21: 45129 | D21: Billing Query | E21: 65.5 | F21: N/A | G21: In Progress
A22: TKT-0021 | B22: CLI-039 | C22: 45509 | D22: Data Sync Error | E22: 0 | F22: 4 | G22: Open
A23: TKT-0022 | B23: CLI-039 | C23: 44967 | D23: Integration Help | E23: 43.7 | F23: N/A | G23: Pending
A24: TKT-0023 | B24: CLI-053 | C24: 45202 | D24: Feature Request | E24: 0 | F24: 1 | G24: Closed
A25: TKT-0024 | B25: CLI-023 | C25: 45345 | D25: Integration Help | E25: -3 | F25: N/A | G25: Escalated
A26: TKT-0025 | B26: CLI-036 | C26: 44964 | D26: Billing Query | E26: 23 | F26: N/A | G26: Escalated
A27: TKT-0026 | B27: CLI-035 | C27: 45400 | D27: Login Issue | E27: 45.2 | F27: 3 | G27: Open
A28: TKT-0027 | B28: CLI-009 | C28: 45221 | D28: Data Sync Error | E28: 9.2 | F28: 5 | G28: Closed
A29: TKT-0028 | B29: CLI-006 | C29: 45157 | D29: Data Sync Error | E29: 21.4 | F29: 4 | G29: Escalated
A30: TKT-0029 | B30: CLI-031 | C30: 45410 | D30: Data Sync Error | E30: 27.9 | F30: 3 | G30: Escalated
A31: TKT-0030 | B31: CLI-051 | C31: 45351 | D31: Onboarding Help | E31: 0 | F31: N/A | G31: Closed
A32: TKT-0031 | B32: CLI-029 | C32: 45478 | D32: Integration Help | E32: 67.2 | F32: 5 | G32: Closed
A33: TKT-0032 | B33: CLI-015 | C33: 45347 | D33: Integration Help | E33: 58.5 | F33: 4 | G33: Open
A34: TKT-0033 | B34: CLI-009 | C34: 45441 | D34: Billing Query | E34: -3 | F34: N/A | G34: Pending
A35: TKT-0034 | B35: CLI-010 | C35: 45003 | D35: Bug Report | E35: -3 | F35: 3 | G35: Pending
A36: TKT-0035 | B36: CLI-046 | C36: 45426 | D36: Billing Query | E36: 49.4 | F36: N/A | G36: Pending
A37: TKT-0036 | B37: CLI-046 | C37: 45029 | D37: Feature Request | E37: N/A | F37: 4 | G37: Closed
A38: TKT-0037 | B38: CLI-016 | C38: 45470 | D38: Feature Request | E38: 62.8 | F38: 2 | G38: Closed
A39: TKT-0038 | B39: CLI-041 | C39: 45187 | D39: Bug Report | E39: 64.8 | F39: 4 | G39: In Progress
A40: TKT-0039 | B40: CLI-038 | C40: 45233 | D40: Bug Report | E40: -3 | F40: 5 | G40: In Progress
...

Sheet Sheet1
A1: Total revenue by region, by product category, and by sales rep.
B4: ProductID | C4: Category | D4: RepID | E4: Revenue | F4: Region
B5: PRD-07 | C5: =_xlfn.XLOOKUP(B5,Products!$A$2:$A$251,Products!$C$2:$C$251) -> Analytics AI | D5: =_xlfn.XLOOKUP(B5,Sales_Transactions!D$2:D$251,Sales_Transactions!E$2:E$251) -> REP-07 | E5: N/A | F5: Asia-Pacific | I5: Sum of Revenue | J5: RepID
B6: PRD-04 | C6: =_xlfn.XLOOKUP(B6,Products!$A$2:$A$251,Products!$C$2:$C$251) -> Conversational AI | D6: =_xlfn.XLOOKUP(B6,Sales_Transactions!D$2:D$251,Sales_Transactions!E$2:E$251) -> REP-04 | E6: 640 | F6: North America | I6: Region | J6: REP-01 | K6: REP-02 | L6: REP-03 | M6: REP-04 | N6: REP-07 | O6: REP-09 | P6: REP-11 | Q6: REP-12 | R6: Grand Total
B7: PRD-02 | C7: =_xlfn.XLOOKUP(B7,Products!$A$2:$A$251,Products!$C$2:$C$251) -> Sales AI | D7: =_xlfn.XLOOKUP(B7,Sales_Transactions!D$2:D$251,Sales_Transactions!E$2:E$251) -> REP-04 | E7: N/A | F7: N/A | I7: Asia-Pacific | J7: 0 | K7: 8850 | L7: 22790 | M7: 8360 | N7: 4812.5 | O7: 24125 | P7: 8835 | Q7: 12400 | R7: 90172.5
B8: PRD-12 | C8: =_xlfn.XLOOKUP(B8,Products!$A$2:$A$251,Products!$C$2:$C$251) -> Conversational AI | D8: =_xlfn.XLOOKUP(B8,Sales_Transactions!D$2:D$251,Sales_Transactions!E$2:E$251) -> REP-01 | E8: 0 | F8: N/A | I8: Europe | J8: 2145 | K8: 35250 | L8: 16150 | M8: 4000 | N8: 11375 | O8: 2905 | P8: 8512.5 | Q8: 4800 | R8: 85137.5
B9: PRD-03 | C9: =_xlfn.XLOOKUP(B9,Products!$A$2:$A$251,Products!$C$2:$C$251) -> Conversational AI | D9: =_xlfn.XLOOKUP(B9,Sales_Transactions!D$2:D$251,Sales_Transactions!E$2:E$251) -> REP-02 | E9: 2850 | F9: Asia-Pacific | I9: India | J9: 4180 | K9: 0 | L9: 34240 | M9: 3780 | N9: 2975 | O9: 3180 | P9: 15580 | Q9: -1600 | R9: 62335
B10: PRD-12 | C10: =_xlfn.XLOOKUP(B10,Products!$A$2:$A$251,Products!$C$2:$C$251) -> Conversational AI | D10: =_xlfn.XLOOKUP(B10,Sales_Transactions!D$2:D$251,Sales_Transactions!E$2:E$251) -> REP-01 | E10: 5225 | F10: N/A | I10: Middle East and Africa | J10: 2805 | K10: 13875 | L10: 8990 | M10: 6160 | N10: 7875 | O10: 15480 | P10: 14350 | Q10: 34900 | R10: 104435
B11: PRD-10 | C11: =_xlfn.XLOOKUP(B11,Products!$A$2:$A$251,Products!$C$2:$C$251) -> Security AI | D11: =_xlfn.XLOOKUP(B11,Sales_Transactions!D$2:D$251,Sales_Transactions!E$2:E$251) -> REP-03 | E11: 5415 | F11: India | I11: N/A | J11: 15675 | K11: 0 | L11: 3135 | M11: 1320 | N11: 5950 | O11: 11070 | P11: 4100 | Q11: 6100 | R11: 47350
B12: PRD-05 | C12: =_xlfn.XLOOKUP(B12,Products!$A$2:$A$251,Products!$C$2:$C$251) -> Data AI | D12: =_xlfn.XLOOKUP(B12,Sales_Transactions!D$2:D$251,Sales_Transactions!E$2:E$251) -> REP-12 | E12: N/A | F12: India | I12: North America | J12: 18260 | K12: 1575 | L12: 71040 | M12: 15720 | N12: 6300 | O12: 18375 | P12: 1825 | Q12: 0 | R12: 133095
B13: PRD-10 | C13: =_xlfn.XLOOKUP(B13,Products!$A$2:$A$251,Products!$C$2:$C$251) -> Security AI | D13: =_xlfn.XLOOKUP(B13,Sales_Transactions!D$2:D$251,Sales_Transactions!E$2:E$251) -> REP-03 | E13: 16150 | F13: Europe | I13: Grand Total | J13: 43065 | K13: 59550 | L13: 156345 | M13: 39340 | N13: 39287.5 | O13: 75135 | P13: 53202.5 | Q13: 56600 | R13: 522525
B14: PRD-08 | C14: =_xlfn.XLOOKUP(B14,Products!$A$2:$A$251,Products!$C$2:$C$251) -> Computer Vision | D14: =_xlfn.XLOOKUP(B14,Sales_Transactions!D$2:D$251,Sales_Transactions!E$2:E$251) -> REP-03 | E14: N/A | F14: India
B15: PRD-12 | C15: =_xlfn.XLOOKUP(B15,Products!$A$2:$A$251,Products!$C$2:$C$251) -> Conversational AI | D15: =_xlfn.XLOOKUP(B15,Sales_Transactions!D$2:D$251,Sales_Transactions!E$2:E$251) -> REP-01 | E15: 4180 | F15: North America
B16: PRD-01 | C16: =_xlfn.XLOOKUP(B16,Products!$A$2:$A$251,Products!$C$2:$C$251) -> Sales AI | D16: =_xlfn.XLOOKUP(B16,Sales_Transactions!D$2:D$251,Sales_Transactions!E$2:E$251) -> REP-09 | E16: 3420 | F16: Asia-Pacific
B17: PRD-11 | C17: =_xlfn.XLOOKUP(B17,Products!$A$2:$A$251,Products!$C$2:$C$251) -> Generative AI | D17: =_xlfn.XLOOKUP(B17,Sales_Transactions!D$2:D$251,Sales_Transactions!E$2:E$251) -> REP-11 | E17: 1900 | F17: N/A
B18: PRD-02 | C18: =_xlfn.XLOOKUP(B18,Products!$A$2:$A$251,Products!$C$2:$C$251) -> Sales AI | D18: =_xlfn.XLOOKUP(B18,Sales_Transactions!D$2:D$251,Sales_Transactions!E$2:E$251) -> REP-04 | E18: N/A | F18: North America
B19: PRD-06 | C19: =_xlfn.XLOOKUP(B19,Products!$A$2:$A$251,Products!$C$2:$C$251) -> Analytics AI | D19: =_xlfn.XLOOKUP(B19,Sales_Transactions!D$2:D$251,Sales_Transactions!E$2:E$251) -> REP-11 | E19: 950 | F19: N/A
B20: PRD-06 | C20: =_xlfn.XLOOKUP(B20,Products!$A$2:$A$251,Products!$C$2:$C$251) -> Analytics AI | D20: =_xlfn.XLOOKUP(B20,Sales_Transactions!D$2:D$251,Sales_Transactions!E$2:E$251) -> REP-11 | E20: 4512.5 | F20: Europe
B21: PRD-11 | C21: =_xlfn.XLOOKUP(B21,Products!$A$2:$A$251,Products!$C$2:$C$251) -> Generative AI | D21: =_xlfn.XLOOKUP(B21,Sales_Transactions!D$2:D$251,Sales_Transactions!E$2:E$251) -> REP-11 | E21: N/A | F21: India
B22: PRD-09 | C22: =_xlfn.XLOOKUP(B22,Products!$A$2:$A$251,Products!$C$2:$C$251) -> HR AI | D22: =_xlfn.XLOOKUP(B22,Sales_Transactions!D$2:D$251,Sales_Transactions!E$2:E$251) -> REP-09 | E22: N/A | F22: India
B23: PRD-12 | C23: =_xlfn.XLOOKUP(B23,Products!$A$2:$A$251,Products!$C$2:$C$251) -> Conversational AI | D23: =_xlfn.XLOOKUP(B23,Sales_Transactions!D$2:D$251,Sales_Transactions!E$2:E$251) -> REP-01 | E23: N/A | F23: India
B24: PRD-11 | C24: =_xlfn.XLOOKUP(B24,Products!$A$2:$A$251,Products!$C$2:$C$251) -> Generative AI | D24: =_xlfn.XLOOKUP(B24,Sales_Transactions!D$2:D$251,Sales_Transactions!E$2:E$251) -> REP-11 | E24: -450 | F24: N/A
B25: PRD-11 | C25: =_xlfn.XLOOKUP(B25,Products!$A$2:$A$251,Products!$C$2:$C$251) -> Generative AI | D25: =_xlfn.XLOOKUP(B25,Sales_Transactions!D$2:D$251,Sales_Transactions!E$2:E$251) -> REP-11 | E25: 0 | F25: Middle East and Africa
B26: PRD-10 | C26: =_xlfn.XLOOKUP(B26,Products!$A$2:$A$251,Products!$C$2:$C$251) -> Security AI | D26: =_xlfn.XLOOKUP(B26,Sales_Transactions!D$2:D$251,Sales_Transactions!E$2:E$251) -> REP-03 | E26: 1900 | F26: North America
B27: PRD-09 | C27: =_xlfn.XLOOKUP(B27,Products!$A$2:$A$251,Products!$C$2:$C$251) -> HR AI | D27: =_xlfn.XLOOKUP(B27,Sales_Transactions!D$2:D$251,Sales_Transactions!E$2:E$251) -> REP-09 | E27: 1190 | F27: North America
B28: PRD-08 | C28: =_xlfn.XLOOKUP(B28,Products!$A$2:$A$251,Products!$C$2:$C$251) -> Computer Vision | D28: =_xlfn.XLOOKUP(B28,Sales_Transactions!D$2:D$251,Sales_Transactions!E$2:E$251) -> REP-03 | E28: 3960 | F28: North America
B29: PRD-06 | C29: =_xlfn.XLOOKUP(B29,Products!$A$2:$A$251,Products!$C$2:$C$251) -> Analytics AI | D29: =_xlfn.XLOOKUP(B29,Sales_Transactions!D$2:D$251,Sales_Transactions!E$2:E$251) -> REP-11 | E29: N/A | F29: Middle East and Africa
B30: PRD-07 | C30: =_xlfn.XLOOKUP(B30,Products!$A$2:$A$251,Products!$C$2:$C$251) -> Analytics AI | D30: =_xlfn.XLOOKUP(B30,Sales_Transactions!D$2:D$251,Sales_Transactions!E$2:E$251) -> REP-07 | E30: N/A | F30: Europe
B31: PRD-11 | C31: =_xlfn.XLOOKUP(B31,Products!$A$2:$A$251,Products!$C$2:$C$251) -> Generative AI | D31: =_xlfn.XLOOKUP(B31,Sales_Transactions!D$2:D$251,Sales_Transactions!E$2:E$251) -> REP-11 | E31: 1700 | F31: N/A
B32: PRD-05 | C32: =_xlfn.XLOOKUP(B32,Products!$A$2:$A$251,Products!$C$2:$C$251) -> Data AI | D32: =_xlfn.XLOOKUP(B32,Sales_Transactions!D$2:D$251,Sales_Transactions!E$2:E$251) -> REP-12 | E32: N/A | F32: Europe
B33: PRD-09 | C33: =_xlfn.XLOOKUP(B33,Products!$A$2:$A$251,Products!$C$2:$C$251) -> HR AI | D33: =_xlfn.XLOOKUP(B33,Sales_Transactions!D$2:D$251,Sales_Transactions!E$2:E$251) -> REP-09 | E33: 2800 | F33: Asia-Pacific
B34: PRD-06 | C34: =_xlfn.XLOOKUP(B34,Products!$A$2:$A$251,Products!$C$2:$C$251) -> Analytics AI | D34: =_xlfn.XLOOKUP(B34,Sales_Transactions!D$2:D$251,Sales_Transactions!E$2:E$251) -> REP-11 | E34: N/A | F34: India
B35: PRD-09 | C35: =_xlfn.XLOOKUP(B35,Products!$A$2:$A$251,Products!$C$2:$C$251) -> HR AI | D35: =_xlfn.XLOOKUP(B35,Sales_Transactions!D$2:D$251,Sales_Transactions!E$2:E$251) -> REP-09 | E35: N/A | F35: North America
B36: PRD-08 | C36: =_xlfn.XLOOKUP(B36,Products!$A$2:$A$251,Products!$C$2:$C$251) -> Computer Vision | D36: =_xlfn.XLOOKUP(B36,Sales_Transactions!D$2:D$251,Sales_Transactions!E$2:E$251) -> REP-03 | E36: N/A | F36: North America
B37: PRD-02 | C37: =_xlfn.XLOOKUP(B37,Products!$A$2:$A$251,Products!$C$2:$C$251) -> Sales AI | D37: =_xlfn.XLOOKUP(B37,Sales_Transactions!D$2:D$251,Sales_Transactions!E$2:E$251) -> REP-04 | E37: 3200 | F37: Asia-Pacific
B38: PRD-11 | C38: =_xlfn.XLOOKUP(B38,Products!$A$2:$A$251,Products!$C$2:$C$251) -> Generative AI | D38: =_xlfn.XLOOKUP(B38,Sales_Transactions!D$2:D$251,Sales_Transactions!E$2:E$251) -> REP-11 | E38: 4000 | F38: Europe
B39: PRD-12 | C39: =_xlfn.XLOOKUP(B39,Products!$A$2:$A$251,Products!$C$2:$C$251) -> Conversational AI | D39: =_xlfn.XLOOKUP(B39,Sales_Transactions!D$2:D$251,Sales_Transactions!E$2:E$251) -> REP-01 | E39: N/A | F39: Asia-Pacific
B40: PRD-09 | C40: =_xlfn.XLOOKUP(B40,Products!$A$2:$A$251,Products!$C$2:$C$251) -> HR AI | D40: =_xlfn.XLOOKUP(B40,Sales_Transactions!D$2:D$251,Sales_Transactions!E$2:E$251) -> REP-09 | E40: N/A | F40: N/A
B41: PRD-12 | C41: =_xlfn.XLOOKUP(B41,Products!$A$2:$A$251,Products!$C$2:$C$251) -> Conversational AI | D41: =_xlfn.XLOOKUP(B41,Sales_Transactions!D$2:D$251,Sales_Transactions!E$2:E$251) -> REP-01 | E41: -990 | F41: Europe
B42: PRD-10 | C42: =_xlfn.XLOOKUP(B42,Products!$A$2:$A$251,Products!$C$2:$C$251) -> Security AI | D42: =_xlfn.XLOOKUP(B42,Sales_Transactions!D$2:D$251,Sales_Transactions!E$2:E$251) -> REP-03 | E42: N/A | F42: Europe
...

Sheet Sheet2
A1: Top 10 clients by total revenue
B4: ClientID | C4: Revenue
B5: CLI-043 | C5: N/A
B6: CLI-025 | C6: 640
B7: CLI-056 | C7: N/A | F7: ClientID | G7: Sum of Revenue | H7: CompanyName
B8: CLI-012 | C8: 0 | F8: CLI-013 | G8: 46150 | H8: =_xlfn.XLOOKUP(F8,Clients!A$2:A$61,Clients!B$2:B$61) -> Silverline Systems
B9: CLI-042 | C9: 2850 | F9: CLI-004 | G9: 32830 | H9: =_xlfn.XLOOKUP(F9,Clients!A$2:A$61,Clients!B$2:B$61) -> Kestrel Labs
B10: CLI-026 | C10: 5225 | F10: CLI-046 | G10: 26730 | H10: =_xlfn.XLOOKUP(F10,Clients!A$2:A$61,Clients!B$2:B$61) -> Aurelia Systems
B11: CLI-032 | C11: 5415 | F11: CLI-021 | G11: 21500 | H11: =_xlfn.XLOOKUP(F11,Clients!A$2:A$61,Clients!B$2:B$61) -> Brightmind Solutions
B12: CLI-048 | C12: N/A | F12: CLI-006 | G12: 21330 | H12: =_xlfn.XLOOKUP(F12,Clients!A$2:A$61,Clients!B$2:B$61) -> Solara Systems
B13: CLI-013 | C13: 16150 | F13: CLI-037 | G13: 19965 | H13: =_xlfn.XLOOKUP(F13,Clients!A$2:A$61,Clients!B$2:B$61) -> Vertex Retail
B14: CLI-009 | C14: N/A | F14: CLI-051 | G14: 19800 | H14: =_xlfn.XLOOKUP(F14,Clients!A$2:A$61,Clients!B$2:B$61) -> Nexora Consulting
B15: CLI-033 | C15: 4180 | F15: CLI-002 | G15: 18030 | H15: =_xlfn.XLOOKUP(F15,Clients!A$2:A$61,Clients!B$2:B$61) -> Brightmind Finance Group
B16: CLI-007 | C16: 3420 | F16: CLI-052 | G16: 18000 | H16: =_xlfn.XLOOKUP(F16,Clients!A$2:A$61,Clients!B$2:B$61) -> Meridian Systems
B17: CLI-006 | C17: 1900 | F17: CLI-031 | G17: 17167.5 | H17: =_xlfn.XLOOKUP(F17,Clients!A$2:A$61,Clients!B$2:B$61) -> Thornton Global
B18: CLI-009 | C18: N/A | F18: Grand Total | G18: =SUM(G8:G17) -> 241502.5
B19: CLI-022 | C19: 950
B20: CLI-060 | C20: 4512.5
B21: CLI-003 | C21: N/A
B22: CLI-003 | C22: 3300
B23: CLI-054 | C23: N/A
B24: CLI-056 | C24: N/A
B25: CLI-030 | C25: -450
B26: CLI-057 | C26: 0
B27: CLI-030 | C27: 1900
B28: CLI-050 | C28: 1190
B29: CLI-016 | C29: 3960
B30: CLI-013 | C30: N/A
B31: CLI-014 | C31: N/A
B32: CLI-057 | C32: 1700
B33: CLI-035 | C33: N/A
B34: CLI-037 | C34: 2800
B35: CLI-004 | C35: N/A
B36: CLI-022 | C36: N/A
B37: CLI-012 | C37: N/A
B38: CLI-037 | C38: 3200
B39: CLI-026 | C39: 4000
B40: CLI-051 | C40: N/A
B41: CLI-002 | C41: N/A
B42: CLI-018 | C42: -990
...

Sheet Sheet3
A1: Month-over-month revenue trend for the full period
B4: OrderDate | C4: Month | D4: Revenue
B5: 44956 | C5: =TEXT(B5,"mmmm") -> January | D5: =_xlfn.XLOOKUP(B5,Sales_Transactions!B$2:B$251,Sales_Transactions!M$2:M$251) -> N/A
B6: 45398 | C6: =TEXT(B6,"mmmm") -> April | D6: =_xlfn.XLOOKUP(B6,Sales_Transactions!B$2:B$251,Sales_Transactions!M$2:M$251) -> 640 | F6: Month | G6: Sum of Revenue
B7: 45141 | C7: =TEXT(B7,"mmmm") -> August | D7: =_xlfn.XLOOKUP(B7,Sales_Transactions!B$2:B$251,Sales_Transactions!M$2:M$251) -> N/A | F7: January | G7: 113167.5
B8: 45543 | C8: =TEXT(B8,"mmmm") -> September | D8: =_xlfn.XLOOKUP(B8,Sales_Transactions!B$2:B$251,Sales_Transactions!M$2:M$251) -> 0 | F8: February | G8: 33535
B9: 45062 | C9: =TEXT(B9,"mmmm") -> May | D9: =_xlfn.XLOOKUP(B9,Sales_Transactions!B$2:B$251,Sales_Transactions!M$2:M$251) -> 2850 | F9: March | G9: 40795
B10: 45417 | C10: =TEXT(B10,"mmmm") -> May | D10: =_xlfn.XLOOKUP(B10,Sales_Transactions!B$2:B$251,Sales_Transactions!M$2:M$251) -> 5225 | F10: April | G10: 25260
B11: 45303 | C11: =TEXT(B11,"mmmm") -> January | D11: =_xlfn.XLOOKUP(B11,Sales_Transactions!B$2:B$251,Sales_Transactions!M$2:M$251) -> 5415 | F11: May | G11: 40050
B12: 45304 | C12: =TEXT(B12,"mmmm") -> January | D12: =_xlfn.XLOOKUP(B12,Sales_Transactions!B$2:B$251,Sales_Transactions!M$2:M$251) -> N/A | F12: June | G12: 25700
B13: 45499 | C13: =TEXT(B13,"mmmm") -> July | D13: =_xlfn.XLOOKUP(B13,Sales_Transactions!B$2:B$251,Sales_Transactions!M$2:M$251) -> 16150 | F13: July | G13: 55005
B14: 45392 | C14: =TEXT(B14,"mmmm") -> April | D14: =_xlfn.XLOOKUP(B14,Sales_Transactions!B$2:B$251,Sales_Transactions!M$2:M$251) -> N/A | F14: August | G14: 18882.5
B15: 45483 | C15: =TEXT(B15,"mmmm") -> July | D15: =_xlfn.XLOOKUP(B15,Sales_Transactions!B$2:B$251,Sales_Transactions!M$2:M$251) -> 4180 | F15: September | G15: 89970
B16: 45310 | C16: =TEXT(B16,"mmmm") -> January | D16: =_xlfn.XLOOKUP(B16,Sales_Transactions!B$2:B$251,Sales_Transactions!M$2:M$251) -> 3420 | F16: October | G16: 10450
B17: 45479 | C17: =TEXT(B17,"mmmm") -> July | D17: =_xlfn.XLOOKUP(B17,Sales_Transactions!B$2:B$251,Sales_Transactions!M$2:M$251) -> 1900 | F17: November | G17: 29435
B18: 45368 | C18: =TEXT(B18,"mmmm") -> March | D18: =_xlfn.XLOOKUP(B18,Sales_Transactions!B$2:B$251,Sales_Transactions!M$2:M$251) -> N/A | F18: December | G18: 39125
B19: 45225 | C19: =TEXT(B19,"mmmm") -> October | D19: =_xlfn.XLOOKUP(B19,Sales_Transactions!B$2:B$251,Sales_Transactions!M$2:M$251) -> 950 | F19: Grand Total | G19: 521375
B20: 45139 | C20: =TEXT(B20,"mmmm") -> August | D20: =_xlfn.XLOOKUP(B20,Sales_Transactions!B$2:B$251,Sales_Transactions!M$2:M$251) -> 4512.5
B21: 45198 | C21: =TEXT(B21,"mmmm") -> September | D21: =_xlfn.XLOOKUP(B21,Sales_Transactions!B$2:B$251,Sales_Transactions!M$2:M$251) -> N/A
B22: 45556 | C22: =TEXT(B22,"mmmm") -> September | D22: =_xlfn.XLOOKUP(B22,Sales_Transactions!B$2:B$251,Sales_Transactions!M$2:M$251) -> 3300
B23: 45134 | C23: =TEXT(B23,"mmmm") -> July | D23: =_xlfn.XLOOKUP(B23,Sales_Transactions!B$2:B$251,Sales_Transactions!M$2:M$251) -> N/A
B24: 45280 | C24: =TEXT(B24,"mmmm") -> December | D24: =_xlfn.XLOOKUP(B24,Sales_Transactions!B$2:B$251,Sales_Transactions!M$2:M$251) -> N/A
B25: 45279 | C25: =TEXT(B25,"mmmm") -> December | D25: =_xlfn.XLOOKUP(B25,Sales_Transactions!B$2:B$251,Sales_Transactions!M$2:M$251) -> -450
B26: 45474 | C26: =TEXT(B26,"mmmm") -> July | D26: =_xlfn.XLOOKUP(B26,Sales_Transactions!B$2:B$251,Sales_Transactions!M$2:M$251) -> 0
B27: 45158 | C27: =TEXT(B27,"mmmm") -> August | D27: =_xlfn.XLOOKUP(B27,Sales_Transactions!B$2:B$251,Sales_Transactions!M$2:M$251) -> 1900
B28: 44956 | C28: =TEXT(B28,"mmmm") -> January | D28: =_xlfn.XLOOKUP(B28,Sales_Transactions!B$2:B$251,Sales_Transactions!M$2:M$251) -> N/A
B29: 44936 | C29: =TEXT(B29,"mmmm") -> January | D29: =_xlfn.XLOOKUP(B29,Sales_Transactions!B$2:B$251,Sales_Transactions!M$2:M$251) -> 3960
B30: 45451 | C30: =TEXT(B30,"mmmm") -> June | D30: =_xlfn.XLOOKUP(B30,Sales_Transactions!B$2:B$251,Sales_Transactions!M$2:M$251) -> N/A
B31: 45180 | C31: =TEXT(B31,"mmmm") -> September | D31: =_xlfn.XLOOKUP(B31,Sales_Transactions!B$2:B$251,Sales_Transactions!M$2:M$251) -> N/A
... B254: 45293 | C254: =TEXT(B254,"mmmm") -> January | D254: =_xlfn.XLOOKUP(B254,Sales_Transactions!B$2:B$251,Sales_Transactions!M$2:M$251) -> N/A

Sheet Sheet4
A1: Win rate by sales rep and by team
G3: DealStatus | H3: Rate
G4: Won | H4: 0.304
C7: SalesRepID | D7: DealStatus | E7: Rate | F7: Team
C8: REP-01 | D8: Pending | E8: 0.192 | F8: =_xlfn.XLOOKUP(C8,Sales_Reps!A$2:A$13,Sales_Reps!D$2:D$13) -> Small and Medium-Sized Business
C9: REP-01 | D9: Closed Won | E9: 0.096 | F9: =_xlfn.XLOOKUP(C9,Sales_Reps!A$2:A$13,Sales_Reps!D$2:D$13) -> Small and Medium-Sized Business
C10: REP-01 | D10: Lost | E10: 0.2 | F10: =_xlfn.XLOOKUP(C10,Sales_Reps!A$2:A$13,Sales_Reps!D$2:D$13) -> Small and Medium-Sized Business
C11: REP-01 | D11: Closed Lost | E11: 0.096 | F11: =_xlfn.XLOOKUP(C11,Sales_Reps!A$2:A$13,Sales_Reps!D$2:D$13) -> Small and Medium-Sized Business
C12: REP-01 | D12: Won | E12: 0.304 | F12: =_xlfn.XLOOKUP(C12,Sales_Reps!A$2:A$13,Sales_Reps!D$2:D$13) -> Small and Medium-Sized Business
C13: REP-01 | D13: In Progress | E13: 0.112 | F13: =_xlfn.XLOOKUP(C13,Sales_Reps!A$2:A$13,Sales_Reps!D$2:D$13) -> Small and Medium-Sized Business
C14: REP-02 | D14: Pending | E14: 0.192 | F14: =_xlfn.XLOOKUP(C14,Sales_Reps!A$2:A$13,Sales_Reps!D$2:D$13) -> Small and Medium-Sized Business
C15: REP-02 | D15: Won | E15: 0.304 | F15: =_xlfn.XLOOKUP(C15,Sales_Reps!A$2:A$13,Sales_Reps!D$2:D$13) -> Small and Medium-Sized Business
C16: REP-02 | D16: Lost | E16: 0.2 | F16: =_xlfn.XLOOKUP(C16,Sales_Reps!A$2:A$13,Sales_Reps!D$2:D$13) -> Small and Medium-Sized Business
C17: REP-02 | D17: In Progress | E17: 0.112 | F17: =_xlfn.XLOOKUP(C17,Sales_Reps!A$2:A$13,Sales_Reps!D$2:D$13) -> Small and Medium-Sized Business
C18: REP-02 | D18: Closed Won | E18: 0.096 | F18: =_xlfn.XLOOKUP(C18,Sales_Reps!A$2:A$13,Sales_Reps!D$2:D$13) -> Small and Medium-Sized Business
C19: REP-02 | D19: Closed Lost | E19: 0.096 | F19: =_xlfn.XLOOKUP(C19,Sales_Reps!A$2:A$13,Sales_Reps!D$2:D$13) -> Small and Medium-Sized Business
... C78: REP-12 | D78: In Progress | E78: 0.112 | F78: =_xlfn.XLOOKUP(C78,Sales_Reps!A$2:A$13,Sales_Reps!D$2:D$13) -> Small and Medium-Sized Business
